<sdf version='1.10'>
  <model name='vehicle'>
    <pose>8.7566499999999997e-11 2 0.32500699999999999 -5.0518200000000002e-10 3.1007399999999998e-10 -5.1850100000000003e-12</pose>
    
    <link name='chassis'>
      <pose>-0.15142700000000001 0 0.17499999999999999 0 0 0</pose>
      <inertial>
        <mass>1.14395</mass>
        <inertia>
          <ixx>0.126164</ixx>
          <ixy>0</ixy>
          <ixz>0</ixz>
          <iyy>0.41651899999999997</iyy>
          <iyz>0</iyz>
          <izz>0.481014</izz>
        </inertia>
        <pose>0 0 0 0 0 0</pose>
      </inertial>
      <visual name='visual'>
        <geometry>
          <box>
            <size>2.0114200000000002 1 0.56872599999999995</size>
          </box>
        </geometry>
        <material>
          <ambient>0.5 0.5 1 1</ambient>
          <diffuse>0.5 0.5 1 1</diffuse>
          <specular>0 0 1 1</specular>
        </material>
      </visual>
      <collision name='collision'>
        <geometry>
          <box>
            <size>2.0114200000000002 1 0.56872599999999995</size>
          </box>
        </geometry>
        <surface>
          <friction>
            <ode/>
          </friction>
          <bounce/>
          <contact/>
        </surface>
      </collision>
      <enable_wind>false</enable_wind>
    </link>

    <!-- Front Left Wheel -->
    <link name='front_left_wheel'>
      <pose>0.55428299999999997 0.62502899999999995 -0.025000000000000001 -1.5707 -9.1455600000074297e-15 4.2666000000000005e-10</pose>
      <inertial>
        <mass>2</mass>
        <inertia>
          <ixx>0.14583299999999999</ixx>
          <ixy>0</ixy>
          <ixz>0</ixz>
          <iyy>0.14583299999999999</iyy>
          <iyz>0</iyz>
          <izz>0.125</izz>
        </inertia>
        <pose>0 0 0 0 0 0</pose>
      </inertial>
      <visual name='visual'>
        <geometry>
          <cylinder>
            <length>0.14999999999999999</length>
            <radius>0.29999999999999999</radius>
          </cylinder>
        </geometry>
        <material>
          <ambient>0.200000003 0.200000003 0.200000003 1</ambient>
          <diffuse>0.200000003 0.200000003 0.200000003 1</diffuse>
          <specular>0.200000003 0.200000003 0.200000003 1</specular>
        </material>
      </visual>
      <collision name='collision'>
        <geometry>
          <cylinder>
            <length>0.14999999999999999</length>
            <radius>0.29999999999999999</radius>
          </cylinder>
        </geometry>
        <surface>
          <friction>
            <ode>
              <mu>0.5</mu>
              <mu2>1</mu2>
              <fdir1>0 0 1</fdir1>
            </ode>
            <bullet>
              <friction>0.5</friction>
              <friction2>1</friction2>
              <rolling_friction>0.10000000000000001</rolling_friction>
            </bullet>
          </friction>
          <bounce/>
          <contact/>
        </surface>
      </collision>
      <enable_wind>false</enable_wind>
    </link>

    <!-- Rear Left Wheel -->
    <link name='rear_left_wheel'>
      <pose>-0.95713800000000004 0.62502899999999995 -0.025000000000000001 -1.5707 -2.9522299999999999e-15 -2.8437899999995768e-19</pose>
      <inertial>
        <mass>2</mass>
        <inertia>
          <ixx>0.14583299999999999</ixx>
          <ixy>0</ixy>
          <ixz>0</ixz>
          <iyy>0.14583299999999999</iyy>
          <iyz>0</iyz>
          <izz>0.125</izz>
        </inertia>
        <pose>0 0 0 0 0 0</pose>
      </inertial>
      <visual name='visual'>
        <geometry>
          <cylinder>
            <length>0.14999999999999999</length>
            <radius>0.29999999999999999</radius>
          </cylinder>
        </geometry>
        <material>
          <ambient>0.200000003 0.200000003 0.200000003 1</ambient>
          <diffuse>0.200000003 0.200000003 0.200000003 1</diffuse>
          <specular>0.200000003 0.200000003 0.200000003 1</specular>
        </material>
      </visual>
      <collision name='collision'>
        <geometry>
          <cylinder>
            <length>0.14999999999999999</length>
            <radius>0.29999999999999999</radius>
          </cylinder>
        </geometry>
        <surface>
          <friction>
            <ode>
              <mu>0.5</mu>
              <mu2>1</mu2>
              <fdir1>0 0 1</fdir1>
            </ode>
            <bullet>
              <friction>0.5</friction>
              <friction2>1</friction2>
              <rolling_friction>0.5</rolling_friction>
            </bullet>
          </friction>
          <bounce/>
          <contact/>
        </surface>
      </collision>
      <enable_wind>false</enable_wind>
    </link>

    <!-- Front Right Wheel -->
    <link name='front_right_wheel'>
      <pose>0.55428200000000005 -0.62502899999999995 -0.025000000000000001 -1.5707 1.6772700000030779e-14 4.2665500000000001e-10</pose>
      <inertial>
        <mass>2</mass>
        <inertia>
          <ixx>0.14583299999999999</ixx>
          <ixy>0</ixy>
          <ixz>0</ixz>
          <iyy>0.14583299999999999</iyy>
          <iyz>0</iyz>
          <izz>0.125</izz>
        </inertia>
        <pose>0 0 0 0 0 0</pose>
      </inertial>
      <visual name='visual'>
        <geometry>
          <cylinder>
            <length>0.14999999999999999</length>
            <radius>0.29999999999999999</radius>
          </cylinder>
        </geometry>
        <material>
          <ambient>0.200000003 0.200000003 0.200000003 1</ambient>
          <diffuse>0.200000003 0.200000003 0.200000003 1</diffuse>
          <specular>0.200000003 0.200000003 0.200000003 1</specular>
        </material>
      </visual>
      <collision name='collision'>
        <geometry>
          <cylinder>
            <length>0.14999999999999999</length>
            <radius>0.29999999999999999</radius>
          </cylinder>
        </geometry>
        <surface>
          <friction>
            <ode>
              <mu>0.5</mu>
              <mu2>1</mu2>
              <fdir1>0 0 1</fdir1>
            </ode>
            <bullet>
              <friction>0.5</friction>
              <friction2>1</friction2>
              <rolling_friction>0.10000000000000001</rolling_friction>
            </bullet>
          </friction>
          <bounce/>
          <contact/>
        </surface>
      </collision>
      <enable_wind>false</enable_wind>
    </link>

    <!-- Rear Right Wheel -->
    <link name='rear_right_wheel'>
      <pose>-0.95713800000000004 -0.62502899999999995 -0.025000000000000001 -1.5707 -4.6792399999999999e-15 -4.5073599999923385e-19</pose>
      <inertial>
        <mass>2</mass>
        <inertia>
          <ixx>0.14583299999999999</ixx>
          <ixy>0</ixy>
          <ixz>0</ixz>
          <iyy>0.14583299999999999</iyy>
          <iyz>0</iyz>
          <izz>0.125</izz>
        </inertia>
        <pose>0 0 0 0 0 0</pose>
      </inertial>
      <visual name='visual'>
        <geometry>
          <cylinder>
            <length>0.14999999999999999</length>
            <radius>0.29999999999999999</radius>
          </cylinder>
        </geometry>
        <material>
          <ambient>0.200000003 0.200000003 0.200000003 1</ambient>
          <diffuse>0.200000003 0.200000003 0.200000003 1</diffuse>
          <specular>0.200000003 0.200000003 0.200000003 1</specular>
        </material>
      </visual>
      <collision name='collision'>
        <geometry>
          <cylinder>
            <length>0.14999999999999999</length>
            <radius>0.29999999999999999</radius>
          </cylinder>
        </geometry>
        <surface>
          <friction>
            <ode>
              <mu>0.5</mu>
              <mu2>1</mu2>
              <fdir1>0 0 1</fdir1>
            </ode>
            <bullet>
              <friction>0.5</friction>
              <friction2>1</friction2>
              <rolling_friction>0.5</rolling_friction>
            </bullet>
          </friction>
          <bounce/>
          <contact/>
        </surface>
      </collision>
      <enable_wind>false</enable_wind>
    </link>

    <!-- Front Left Wheel Steering Link -->
    <link name='front_left_wheel_steering_link'>
      <pose>0.55428299999999997 0.5 0.02 4.2778000000000002e-26 4.8520100000000002e-26 4.2666e-10</pose>
      <inertial>
        <mass>0.5</mass>
        <inertia>
          <ixx>0.015299999999999999</ixx>
          <iyy>0.025000000000000001</iyy>
          <izz>0.015299999999999999</izz>
          <ixy>0</ixy>
          <ixz>0</ixz>
          <iyz>0</iyz>
        </inertia>
        <pose>0 0 0 0 0 0</pose>
      </inertial>
      <visual name='steering_link_visual'>
        <pose>0 0 0 0 0 0</pose>
        <geometry>
          <cylinder>
            <length>0.10000000000000001</length>
            <radius>0.029999999999999999</radius>
          </cylinder>
        </geometry>
        <material>
          <ambient>1 1 1 1</ambient>
          <diffuse>1 1 1 1</diffuse>
        </material>
      </visual>
      <enable_wind>false</enable_wind>
    </link>

    <!-- Front Right Wheel Steering Link -->
    <link name='front_right_wheel_steering_link'>
      <pose>0.55428299999999997 -0.5 0.02 -4.5858299999999997e-27 -5.4877400000000003e-26 4.2665500000000001e-10</pose>
      <inertial>
        <mass>0.5</mass>
        <inertia>
          <ixx>0.015299999999999999</ixx>
          <iyy>0.025000000000000001</iyy>
          <izz>0.015299999999999999</izz>
          <ixy>0</ixy>
          <ixz>0</ixz>
          <iyz>0</iyz>
        </inertia>
        <pose>0 0 0 0 0 0</pose>
      </inertial>
      <visual name='steering_link_visual'>
        <pose>0 0 0 0 0 0</pose>
        <geometry>
          <cylinder>
            <length>0.10000000000000001</length>
            <radius>0.029999999999999999</radius>
          </cylinder>
        </geometry>
        <material>
          <ambient>1 1 1 1</ambient>
          <diffuse>1 1 1 1</diffuse>
        </material>
      </visual>
      <enable_wind>false</enable_wind>
    </link>

    <!-- Joints -->
    <joint name='front_left_wheel_steering_joint' type='revolute'>
      <child>front_left_wheel_steering_link</child>
      <parent>chassis</parent>
      <axis>
        <xyz>0 0 1</xyz>
        <limit>
          <lower>-0.59999999999999998</lower>
          <upper>0.59999999999999998</upper>
          <effort>25</effort>
          <velocity>1</velocity>
          <stiffness>100000000</stiffness>
          <dissipation>1</dissipation>
        </limit>
        <dynamics>
          <spring_reference>0</spring_reference>
          <spring_stiffness>0</spring_stiffness>
          <damping>0</damping>
          <friction>0</friction>
        </dynamics>
      </axis>
      <pose>0 0 0 0 0 0</pose>
    </joint>

    <joint name='front_right_wheel_steering_joint' type='revolute'>
      <parent>chassis</parent>
      <child>front_right_wheel_steering_link</child>
      <axis>
        <xyz>0 0 1</xyz>
        <limit>
          <lower>-0.59999999999999998</lower>
          <upper>0.59999999999999998</upper>
          <effort>25</effort>
          <velocity>1</velocity>
          <stiffness>100000000</stiffness>
          <dissipation>1</dissipation>
        </limit>
        <dynamics>
          <spring_reference>0</spring_reference>
          <spring_stiffness>0</spring_stiffness>
          <damping>0</damping>
          <friction>0</friction>
        </dynamics>
      </axis>
      <pose>0 0 0 0 0 0</pose>
    </joint>

    <joint name='front_left_wheel_joint' type='revolute'>
      <parent>front_left_wheel_steering_link</parent>
      <child>front_left_wheel</child>
      <axis>
        <xyz>0 0 1</xyz>
        <limit>
          <lower>-1.7976900000000001e+308</lower>
          <upper>1.7976900000000001e+308</upper>
          <effort>inf</effort>
          <velocity>inf</velocity>
          <stiffness>100000000</stiffness>
          <dissipation>1</dissipation>
        </limit>
        <dynamics>
          <spring_reference>0</spring_reference>
          <spring_stiffness>0</spring_stiffness>
          <damping>0</damping>
          <friction>0</friction>
        </dynamics>
      </axis>
      <pose>0 0 1.11022e-16 0 0 0</pose>
    </joint>

    <joint name='front_right_wheel_joint' type='revolute'>
      <parent>front_right_wheel_steering_link</parent>
      <child>front_right_wheel</child>
      <axis>
        <xyz>0 0 1</xyz>
        <limit>
          <lower>-1.7976900000000001e+308</lower>
          <upper>1.7976900000000001e+308</upper>
          <effort>inf</effort>
          <velocity>inf</velocity>
          <stiffness>100000000</stiffness>
          <dissipation>1</dissipation>
        </limit>
        <dynamics>
          <spring_reference>0</spring_reference>
          <spring_stiffness>0</spring_stiffness>
          <damping>0</damping>
          <friction>0</friction>
        </dynamics>
      </axis>
      <pose>-1.11022e-16 0 0 0 0 0</pose>
    </joint>

    <joint name='rear_left_wheel_joint' type='revolute'>
      <parent>chassis</parent>
      <child>rear_left_wheel</child>
      <axis>
        <xyz>0 0 1</xyz>
        <limit>
          <lower>-1.7976900000000001e+308</lower>
          <upper>1.7976900000000001e+308</upper>
          <effort>inf</effort>
          <velocity>inf</velocity>
          <stiffness>100000000</stiffness>
          <dissipation>1</dissipation>
        </limit>
        <dynamics>
          <spring_reference>0</spring_reference>
          <spring_stiffness>0</spring_stiffness>
          <damping>0</damping>
          <friction>0</friction>
        </dynamics>
      </axis>
      <pose>0 0 1.11022e-16 0 0 0</pose>
    </joint>

    <joint name='rear_right_wheel_joint' type='revolute'>
      <parent>chassis</parent>
      <child>rear_right_wheel</child>
      <axis>
        <xyz>0 0 1</xyz>
        <limit>
          <lower>-1.7976900000000001e+308</lower>
          <upper>1.7976900000000001e+308</upper>
          <effort>inf</effort>
          <velocity>inf</velocity>
          <stiffness>100000000</stiffness>
          <dissipation>1</dissipation>
        </limit>
        <dynamics>
          <spring_reference>0</spring_reference>
          <spring_stiffness>0</spring_stiffness>
          <damping>0</damping>
          <friction>0</friction>
        </dynamics>
      </axis>
      <pose>0 0 0 0 0 0</pose>
    </joint>

    <!-- Ackermann Steering Plugin -->
    <plugin name='gz::sim::systems::AckermannSteering' filename='gz-sim-ackermann-steering-system'>
      <left_joint>front_left_wheel_joint</left_joint>
      <left_joint>rear_left_wheel_joint</left_joint>
      <right_joint>front_right_wheel_joint</right_joint>
      <right_joint>rear_right_wheel_joint</right_joint>
      <left_steering_joint>front_left_wheel_steering_joint</left_steering_joint>
      <right_steering_joint>front_right_wheel_steering_joint</right_steering_joint>
      <kingpin_width>1.0</kingpin_width>
      <steering_limit>0.5</steering_limit>
      <wheel_base>1.0</wheel_base>
      <wheel_separation>1.25</wheel_separation>
      <wheel_radius>0.3</wheel_radius>
      <min_velocity>-1</min_velocity>
      <max_velocity>1</max_velocity>
      <min_acceleration>-3</min_acceleration>
      <max_acceleration>3</max_acceleration>
    </plugin>

    <plugin
        filename="gz-sim-diff-drive-system"
        name="gz::sim::systems::DiffDrive">
        <left_joint>left_wheel_joint</left_joint>
        <right_joint>right_wheel_joint</right_joint>
        <wheel_separation>1.25</wheel_separation>
        <wheel_radius>0.3</wheel_radius>  
        <odom_publish_frequency>1</odom_publish_frequency>
      </plugin>
    
    <static>false</static>
    <self_collide>false</self_collide>
  </model>
</sdf>
